Traceback (most recent call last):
  File "/Users/uteamerstorfer/miniconda3/envs/epn-ml-book/lib/python3.9/site-packages/jupyter_cache/executors/utils.py", line 51, in single_nb_execution
    executenb(
  File "/Users/uteamerstorfer/miniconda3/envs/epn-ml-book/lib/python3.9/site-packages/nbclient/client.py", line 1085, in execute
    return NotebookClient(nb=nb, resources=resources, km=km, **kwargs).execute()
  File "/Users/uteamerstorfer/miniconda3/envs/epn-ml-book/lib/python3.9/site-packages/nbclient/util.py", line 84, in wrapped
    return just_run(coro(*args, **kwargs))
  File "/Users/uteamerstorfer/miniconda3/envs/epn-ml-book/lib/python3.9/site-packages/nbclient/util.py", line 62, in just_run
    return loop.run_until_complete(coro)
  File "/Users/uteamerstorfer/miniconda3/envs/epn-ml-book/lib/python3.9/asyncio/base_events.py", line 642, in run_until_complete
    return future.result()
  File "/Users/uteamerstorfer/miniconda3/envs/epn-ml-book/lib/python3.9/site-packages/nbclient/client.py", line 551, in async_execute
    await self.async_execute_cell(
  File "/Users/uteamerstorfer/miniconda3/envs/epn-ml-book/lib/python3.9/site-packages/nbclient/client.py", line 846, in async_execute_cell
    self._check_raise_for_error(cell, exec_reply)
  File "/Users/uteamerstorfer/miniconda3/envs/epn-ml-book/lib/python3.9/site-packages/nbclient/client.py", line 748, in _check_raise_for_error
    raise CellExecutionError.from_cell_and_msg(cell, exec_reply_content)
nbclient.exceptions.CellExecutionError: An error occurred while executing the following cell:
------------------
## BUILT ON THE DEUS VULT VERSION; DISCARD IF IN DOUBT ##

%matplotlib inline
from pylab import rcParams

import warnings

import os, os.path
import pandas as pd, numpy as np, scipy as sp
import matplotlib.pyplot as plt
from datetime import datetime, timedelta

import cufflinks as cf, matplotlib as mp
cf.go_offline()
import matplotlib.pyplot as plt
from matplotlib.dates import DateFormatter 
import matplotlib.dates as mdates
import matplotlib.cm as cm
from matplotlib import dates
from matplotlib.ticker import AutoMinorLocator, LinearLocator, AutoLocator

import plotly.graph_objects as go
from plotly.subplots import make_subplots

from scipy.signal import argrelextrema, find_peaks
from functools import wraps

import ipywidgets as widgets
from ipywidgets import interact, interact_manual, fixed

------------------

[0;31m---------------------------------------------------------------------------[0m
[0;31mModuleNotFoundError[0m                       Traceback (most recent call last)
[0;32m/var/folders/x3/2bzh843n0tv469w6l6sd8sq00000gn/T/ipykernel_23894/1775590290.py[0m in [0;36m<module>[0;34m[0m
[1;32m     11[0m [0;32mfrom[0m [0mdatetime[0m [0;32mimport[0m [0mdatetime[0m[0;34m,[0m [0mtimedelta[0m[0;34m[0m[0;34m[0m[0m
[1;32m     12[0m [0;34m[0m[0m
[0;32m---> 13[0;31m [0;32mimport[0m [0mcufflinks[0m [0;32mas[0m [0mcf[0m[0;34m,[0m [0mmatplotlib[0m [0;32mas[0m [0mmp[0m[0;34m[0m[0;34m[0m[0m
[0m[1;32m     14[0m [0mcf[0m[0;34m.[0m[0mgo_offline[0m[0;34m([0m[0;34m)[0m[0;34m[0m[0;34m[0m[0m
[1;32m     15[0m [0;32mimport[0m [0mmatplotlib[0m[0;34m.[0m[0mpyplot[0m [0;32mas[0m [0mplt[0m[0;34m[0m[0;34m[0m[0m

[0;31mModuleNotFoundError[0m: No module named 'cufflinks'
ModuleNotFoundError: No module named 'cufflinks'

