Traceback (most recent call last):
  File "/Users/uteamerstorfer/miniconda3/envs/epn-ml-book/lib/python3.9/site-packages/nbclient/client.py", line 618, in _async_poll_for_reply
    msg = await ensure_async(self.kc.shell_channel.get_msg(timeout=new_timeout))
  File "/Users/uteamerstorfer/miniconda3/envs/epn-ml-book/lib/python3.9/site-packages/nbclient/util.py", line 96, in ensure_async
    result = await obj
  File "/Users/uteamerstorfer/miniconda3/envs/epn-ml-book/lib/python3.9/site-packages/jupyter_client/channels.py", line 230, in get_msg
    raise Empty
_queue.Empty

During handling of the above exception, another exception occurred:

Traceback (most recent call last):
  File "/Users/uteamerstorfer/miniconda3/envs/epn-ml-book/lib/python3.9/site-packages/jupyter_cache/executors/utils.py", line 51, in single_nb_execution
    executenb(
  File "/Users/uteamerstorfer/miniconda3/envs/epn-ml-book/lib/python3.9/site-packages/nbclient/client.py", line 1085, in execute
    return NotebookClient(nb=nb, resources=resources, km=km, **kwargs).execute()
  File "/Users/uteamerstorfer/miniconda3/envs/epn-ml-book/lib/python3.9/site-packages/nbclient/util.py", line 84, in wrapped
    return just_run(coro(*args, **kwargs))
  File "/Users/uteamerstorfer/miniconda3/envs/epn-ml-book/lib/python3.9/site-packages/nbclient/util.py", line 62, in just_run
    return loop.run_until_complete(coro)
  File "/Users/uteamerstorfer/miniconda3/envs/epn-ml-book/lib/python3.9/asyncio/base_events.py", line 642, in run_until_complete
    return future.result()
  File "/Users/uteamerstorfer/miniconda3/envs/epn-ml-book/lib/python3.9/site-packages/nbclient/client.py", line 551, in async_execute
    await self.async_execute_cell(
  File "/Users/uteamerstorfer/miniconda3/envs/epn-ml-book/lib/python3.9/site-packages/nbclient/client.py", line 830, in async_execute_cell
    exec_reply = await self.task_poll_for_reply
  File "/Users/uteamerstorfer/miniconda3/envs/epn-ml-book/lib/python3.9/site-packages/nbclient/client.py", line 642, in _async_poll_for_reply
    await self._async_handle_timeout(timeout, cell)
  File "/Users/uteamerstorfer/miniconda3/envs/epn-ml-book/lib/python3.9/site-packages/nbclient/client.py", line 689, in _async_handle_timeout
    raise CellTimeoutError.error_from_timeout_and_cell(
nbclient.exceptions.CellTimeoutError: A cell timed out while it was being executed, after 30 seconds.
The message was: Cell execution timed out.
Here is a preview of the cell contents:
-------------------
['import numpy as np', 'import pandas as pd', 'import matplotlib.pyplot as plt', 'import seaborn as sns', 'from sklearn.model_selection import train_test_split']
...
['from sklearn import svm # support vector machine algorithm', 'from sklearn.neighbors import KNeighborsClassifier # K neareast neighbours algorithm', 'from sklearn.linear_model import LogisticRegression # logistic regression algorithm', 'from sklearn.tree import DecisionTreeClassifier # decision tree algorithm', 'from sklearn import metrics # for evaluating the model']
-------------------

